Workbook

Sheet REGISTRO MAESTRO
A1: REGISTRO MAESTRO DE EXPEDIENTES FÍSICOS — INTEGRA LEGAL
A2: Sistema de control y seguimiento de expedientes por clasificación
A4: N° EXP. | B4: N° CLIENTE | C4: CLIENTE | D4: CLASIFICACIÓN | E4: CÓDIGO EXP. | F4: DESCRIPCIÓN DEL ASUNTO | G4: RESPONSABLE | H4: FECHA APERTURA | I4: ESTADO | J4: UBICACIÓN FÍSICA | K4: OBSERVACIONES | L4: ARCHIVO DIGITAL | M4: COLOR
A5: 1 | B5: CLI-001 | C5: =IF(B5="","",_xlfn.XLOOKUP(B5,CLIENTES!$A$4:$A$53,CLIENTES!$B$4:$B$53,"NO ENCONTRADO")) -> JUMBO CAPITAL, S.A. | D5: CORPORATIVO | E5: =IF(D5="","",_xlfn.XLOOKUP(D5,CLASIFICACIONES!$A$4:$A$10,CLASIFICACIONES!$B$4:$B$10,"")&"-"&TEXT(1,"000")) -> CORP-001 | F5: Acta de Reunión Extraordinaria de Accionistas | G5: Daveiva | H5: 13/03/2026 | I5: Activo | J5: Archivo - Sección Clientes | L5: Sí
A6: 2 | B6: CLI-002 | C6: =IF(B6="","",_xlfn.XLOOKUP(B6,CLIENTES!$A$4:$A$53,CLIENTES!$B$4:$B$53,"NO ENCONTRADO")) -> GUILLERMO ROTHPFLUG | D6: CORPORATIVO | E6: =IF(D6="","",_xlfn.XLOOKUP(D6,CLASIFICACIONES!$A$4:$A$10,CLASIFICACIONES!$B$4:$B$10,"")&"-"&TEXT(COUNTIF($D$5:D5,D6)+1,"000")) -> CORP-002 | F6: Sociedad Anónima - VG LOGISTICS | G6: Daveiva | H6: 2021 | I6: Cerrado
A7: 3 | B7: CLI-002 | C7: =IF(B7="","",_xlfn.XLOOKUP(B7,CLIENTES!$A$4:$A$53,CLIENTES!$B$4:$B$53,"NO ENCONTRADO")) -> GUILLERMO ROTHPFLUG | D7: CORPORATIVO | E7: =IF(D7="","",_xlfn.XLOOKUP(D7,CLASIFICACIONES!$A$4:$A$10,CLASIFICACIONES!$B$4:$B$10,"")&"-"&TEXT(COUNTIF($D$5:D6,D7)+1,"000")) -> CORP-003 | F7: Sociedad Anónima - VERION PANAMA, S. A | G7: Daveiva | H7: 2021 | I7: Cerrado
A8: 4 | B8: CLI-002 | C8: =IF(B8="","",_xlfn.XLOOKUP(B8,CLIENTES!$A$4:$A$53,CLIENTES!$B$4:$B$53,"NO ENCONTRADO")) -> GUILLERMO ROTHPFLUG | D8: CORPORATIVO | E8: =IF(D8="","",_xlfn.XLOOKUP(D8,CLASIFICACIONES!$A$4:$A$10,CLASIFICACIONES!$B$4:$B$10,"")&"-"&TEXT(COUNTIF($D$5:D7,D8)+1,"000")) -> CORP-004 | F8: Sociedad Anónima - HIDROMEC, S. A | G8: Daveiva | H8: 2022 | I8: Cerrado
A9: 5 | B9: CLI-003 | C9: =IF(B9="","",_xlfn.XLOOKUP(B9,CLIENTES!$A$4:$A$53,CLIENTES!$B$4:$B$53,"NO ENCONTRADO")) -> RODRIGO MARROQUIN | D9: REGULATORIO | E9: =IF(D9="","",_xlfn.XLOOKUP(D9,CLASIFICACIONES!$A$4:$A$10,CLASIFICACIONES!$B$4:$B$10,"")&"-"&TEXT(COUNTIF($D$5:D8,D9)+1,"000")) -> REG-001 | F9: Obtención de Licencia de Dispositivos Médicos | G9: Daveiva | H9: 46024 | I9: Cerrado | J9: MINSA
A10: 6 | B10: CLI-004 | C10: =IF(B10="","",_xlfn.XLOOKUP(B10,CLIENTES!$A$4:$A$53,CLIENTES!$B$4:$B$53,"NO ENCONTRADO")) -> ERIC REINALDO BATISTA DOMINGUEZ | D10: CORPORATIVO | E10: =IF(D10="","",_xlfn.XLOOKUP(D10,CLASIFICACIONES!$A$4:$A$10,CLASIFICACIONES!$B$4:$B$10,"")&"-"&TEXT(COUNTIF($D$5:D9,D10)+1,"000")) -> CORP-005 | F10: Sociedad DOWNCOUNTRY BIKE CORP. | G10: Daveiva | H10: 17/03/2026 | I10: Activo | J10: CORPORATIVO
A11: 7 | B11: CLI-004 | C11: =IF(B11="","",_xlfn.XLOOKUP(B11,CLIENTES!$A$4:$A$53,CLIENTES!$B$4:$B$53,"NO ENCONTRADO")) -> ERIC REINALDO BATISTA DOMINGUEZ | D11: CORPORATIVO | E11: =IF(D11="","",_xlfn.XLOOKUP(D11,CLASIFICACIONES!$A$4:$A$10,CLASIFICACIONES!$B$4:$B$10,"")&"-"&TEXT(COUNTIF($D$5:D10,D11)+1,"000")) -> CORP-006 | F11: Sociedad GRUPO MELER, S.A. | G11: Daveiva | H11: 17/03/2026 | I11: Activo | J11: CORPORATIVO
A12: 8 | B12: CLI-004 | C12: =IF(B12="","",_xlfn.XLOOKUP(B12,CLIENTES!$A$4:$A$53,CLIENTES!$B$4:$B$53,"NO ENCONTRADO")) -> ERIC REINALDO BATISTA DOMINGUEZ | D12: CORPORATIVO | E12: =IF(D12="","",_xlfn.XLOOKUP(D12,CLASIFICACIONES!$A$4:$A$10,CLASIFICACIONES!$B$4:$B$10,"")&"-"&TEXT(COUNTIF($D$5:D11,D12)+1,"000")) -> CORP-007 | F12: Sociedad GLOBAL SPORT LATAM, INC. | G12: Daveiva | J12: CORPORATIVO
A13: 9 | B13: CLI-005 | C13: =IF(B13="","",_xlfn.XLOOKUP(B13,CLIENTES!$A$4:$A$53,CLIENTES!$B$4:$B$53,"NO ENCONTRADO")) -> MAIKOL FENG | D13: CORPORATIVO | E13: =IF(D13="","",_xlfn.XLOOKUP(D13,CLASIFICACIONES!$A$4:$A$10,CLASIFICACIONES!$B$4:$B$10,"")&"-"&TEXT(COUNTIF($D$5:D12,D13)+1,"000")) -> CORP-008 | F13: Sociedad INMOBILIARIA FUNG, S.A. | G13: Milena | H13: 17/03/2026 | I13: Activo | J13: CORPORATIVO
A14: 10 | B14: CLI-006 | C14: =IF(B14="","",_xlfn.XLOOKUP(B14,CLIENTES!$A$4:$A$53,CLIENTES!$B$4:$B$53,"NO ENCONTRADO")) -> JONATHAN ISAAC MIZRACHI MADURO | D14: CORPORATIVO | E14: =IF(D14="","",_xlfn.XLOOKUP(D14,CLASIFICACIONES!$A$4:$A$10,CLASIFICACIONES!$B$4:$B$10,"")&"-"&TEXT(COUNTIF($D$5:D13,D14)+1,"000")) -> CORP-009 | F14: Sociedad - PPA CONDADO, S.A. | G14: Milena | H14: 20/3/2026 | I14: En trámite | J14: CORPORATIVO
A15: 11 | B15: CLI-007 | C15: =IF(B15="","",_xlfn.XLOOKUP(B15,CLIENTES!$A$4:$A$53,CLIENTES!$B$4:$B$53,"NO ENCONTRADO")) -> LORENA LYA BERENGUER RÍOS | D15: CORPORATIVO | E15: =IF(D15="","",_xlfn.XLOOKUP(D15,CLASIFICACIONES!$A$4:$A$10,CLASIFICACIONES!$B$4:$B$10,"")&"-"&TEXT(COUNTIF($D$5:D14,D15)+1,"000")) -> CORP-010 | F15: Cambios varios | G15: Milena | H15: 2026 | I15: En trámite | J15: CORPORATIVO
A16: 12 | B16: CLI-008 | C16: =IF(B16="","",_xlfn.XLOOKUP(B16,CLIENTES!$A$4:$A$53,CLIENTES!$B$4:$B$53,"NO ENCONTRADO")) -> KURT ARTHUR SÁENZ ALBRECHT | D16: CORPORATIVO | E16: =IF(D16="","",_xlfn.XLOOKUP(D16,CLASIFICACIONES!$A$4:$A$10,CLASIFICACIONES!$B$4:$B$10,"")&"-"&TEXT(COUNTIF($D$5:D15,D16)+1,"000")) -> CORP-011 | F16: Sociedad SAJIMO CORP. | G16: Dave | H16: 16/10/2026 | I16: Activo | J16: CORPORATIVO
A17: 13 | B17: CLI-008 | C17: =IF(B17="","",_xlfn.XLOOKUP(B17,CLIENTES!$A$4:$A$53,CLIENTES!$B$4:$B$53,"NO ENCONTRADO")) -> KURT ARTHUR SÁENZ ALBRECHT | D17: REGULATORIO | E17: =IF(D17="","",_xlfn.XLOOKUP(D17,CLASIFICACIONES!$A$4:$A$10,CLASIFICACIONES!$B$4:$B$10,"")&"-"&TEXT(COUNTIF($D$5:D16,D17)+1,"000")) -> REG-002 | F17: PERMISO SANITARIO CLINICA DENTAL | G17: Dave | H17: 20/3/2026 | I17: En trámite | J17: REGULATORIO
A18: 14 | B18: CLI-009 | C18: =IF(B18="","",_xlfn.XLOOKUP(B18,CLIENTES!$A$4:$A$53,CLIENTES!$B$4:$B$53,"NO ENCONTRADO")) -> DIMEDISA, S.A. | D18: REGULATORIO | E18: =IF(D18="","",_xlfn.XLOOKUP(D18,CLASIFICACIONES!$A$4:$A$10,CLASIFICACIONES!$B$4:$B$10,"")&"-"&TEXT(COUNTIF($D$5:D17,D18)+1,"000")) -> REG-003 | F18: LICENCIA DE FABRICANTE - FYD - CERTIFICACIÓN DE BUENAS PRACTICAS DE MANUFACTURA | G18: Dave | I18: Cerrado | J18: REGULATORIO
A19: 15 | B19: CLI-010 | C19: =IF(B19="","",_xlfn.XLOOKUP(B19,CLIENTES!$A$4:$A$53,CLIENTES!$B$4:$B$53,"NO ENCONTRADO")) -> ANALIDA ARANGO FIDANQUE | D19: CORPORATIVO | E19: =IF(D19="","",_xlfn.XLOOKUP(D19,CLASIFICACIONES!$A$4:$A$10,CLASIFICACIONES!$B$4:$B$10,"")&"-"&TEXT(COUNTIF($D$5:D18,D19)+1,"000")) -> CORP-012 | F19: ALISTANLUCC FOUNDATION | G19: Dave | H19: 2024 | I19: Activo | J19: CORPORATIVO
A20: 16 | B20: CLI-011 | C20: =IF(B20="","",_xlfn.XLOOKUP(B20,CLIENTES!$A$4:$A$53,CLIENTES!$B$4:$B$53,"NO ENCONTRADO")) -> LUIS ANTONIO ZELAYA | D20: CORPORATIVO | E20: =IF(D20="","",_xlfn.XLOOKUP(D20,CLASIFICACIONES!$A$4:$A$10,CLASIFICACIONES!$B$4:$B$10,"")&"-"&TEXT(COUNTIF($D$5:D19,D20)+1,"000")) -> CORP-013 | F20: A & Z GOLDEN, S.A. | G20: Dave | H20: 2024 | I20: Activo | J20: CORPORATIVO
A21: 17 | B21: CLI-012 | C21: =IF(B21="","",_xlfn.XLOOKUP(B21,CLIENTES!$A$4:$A$53,CLIENTES!$B$4:$B$53,"NO ENCONTRADO")) -> DANIEL ALVARADO | D21: CORPORATIVO | E21: =IF(D21="","",_xlfn.XLOOKUP(D21,CLASIFICACIONES!$A$4:$A$10,CLASIFICACIONES!$B$4:$B$10,"")&"-"&TEXT(COUNTIF($D$5:D20,D21)+1,"000")) -> CORP-014 | F21: ALCON TECHNOLOGY SERVICES, S. de R.L. | G21: Dave | H21: 2024 | I21: Activo
A22: 18 | B22: CLI-013 | C22: =IF(B22="","",_xlfn.XLOOKUP(B22,CLIENTES!$A$4:$A$53,CLIENTES!$B$4:$B$53,"NO ENCONTRADO")) -> MADELENE MERCADO | D22: CORPORATIVO | E22: =IF(D22="","",_xlfn.XLOOKUP(D22,CLASIFICACIONES!$A$4:$A$10,CLASIFICACIONES!$B$4:$B$10,"")&"-"&TEXT(COUNTIF($D$5:D21,D22)+1,"000")) -> CORP-015 | F22: AGENTE CORREDOR DE ADUANAS, S.A. | G22: Dave | H22: 2024 | I22: Activo
A23: 19 | B23: CLI-014 | C23: =IF(B23="","",_xlfn.XLOOKUP(B23,CLIENTES!$A$4:$A$53,CLIENTES!$B$4:$B$53,"NO ENCONTRADO")) -> ANGEL RICARDO MARTINEZ BENOIT | D23: CORPORATIVO | E23: =IF(D23="","",_xlfn.XLOOKUP(D23,CLASIFICACIONES!$A$4:$A$10,CLASIFICACIONES!$B$4:$B$10,"")&"-"&TEXT(COUNTIF($D$5:D22,D23)+1,"000")) -> CORP-016 | F23: FUNDACIÓN BARO FORO | G23: Dave | H23: 2024 | I23: Activo
A24: 20 | B24: CLI-015 | C24: =IF(B24="","",_xlfn.XLOOKUP(B24,CLIENTES!$A$4:$A$53,CLIENTES!$B$4:$B$53,"NO ENCONTRADO")) -> MARLENYS IVETH CHACÓN | D24: CORPORATIVO | E24: =IF(D24="","",_xlfn.XLOOKUP(D24,CLASIFICACIONES!$A$4:$A$10,CLASIFICACIONES!$B$4:$B$10,"")&"-"&TEXT(COUNTIF($D$5:D23,D24)+1,"000")) -> CORP-017 | F24: CONSTRUCTORA CHACÓN, S.A. | G24: Dave | H24: 2024 | I24: Activo
A25: 21 | B25: CLI-014 | C25: =IF(B25="","",_xlfn.XLOOKUP(B25,CLIENTES!$A$4:$A$53,CLIENTES!$B$4:$B$53,"NO ENCONTRADO")) -> ANGEL RICARDO MARTINEZ BENOIT | D25: CORPORATIVO | E25: =IF(D25="","",_xlfn.XLOOKUP(D25,CLASIFICACIONES!$A$4:$A$10,CLASIFICACIONES!$B$4:$B$10,"")&"-"&TEXT(COUNTIF($D$5:D24,D25)+1,"000")) -> CORP-018 | F25: COMPAÑÍA TORDEHUMOS, S.A. | G25: Dave | H25: 2025 | I25: Activo
A26: 22 | B26: CLI-016 | C26: =IF(B26="","",_xlfn.XLOOKUP(B26,CLIENTES!$A$4:$A$53,CLIENTES!$B$4:$B$53,"NO ENCONTRADO")) -> YOUSSEF ALI JAAFAR HARB | D26: CORPORATIVO | E26: =IF(D26="","",_xlfn.XLOOKUP(D26,CLASIFICACIONES!$A$4:$A$10,CLASIFICACIONES!$B$4:$B$10,"")&"-"&TEXT(COUNTIF($D$5:D25,D26)+1,"000")) -> CORP-019 | F26: CARAVAN, S.A. | G26: Dave | H26: 2023 | I26: Activo
A27: 23 | B27: CLI-017 | C27: =IF(B27="","",_xlfn.XLOOKUP(B27,CLIENTES!$A$4:$A$53,CLIENTES!$B$4:$B$53,"NO ENCONTRADO")) -> YOM TOB TOBI TAWACHI | D27: CORPORATIVO | E27: =IF(D27="","",_xlfn.XLOOKUP(D27,CLASIFICACIONES!$A$4:$A$10,CLASIFICACIONES!$B$4:$B$10,"")&"-"&TEXT(COUNTIF($D$5:D26,D27)+1,"000")) -> CORP-020 | F27: CATOKETE, S.A. | G27: Dave | H27: 2024 | I27: Activo
A28: 24 | B28: CLI-018 | C28: =IF(B28="","",_xlfn.XLOOKUP(B28,CLIENTES!$A$4:$A$53,CLIENTES!$B$4:$B$53,"NO ENCONTRADO")) -> NAHUEL GALEANO LERNER | D28: CORPORATIVO | E28: =IF(D28="","",_xlfn.XLOOKUP(D28,CLASIFICACIONES!$A$4:$A$10,CLASIFICACIONES!$B$4:$B$10,"")&"-"&TEXT(COUNTIF($D$5:D27,D28)+1,"000")) -> CORP-021 | F28: CLANDESTINO LAB, INC. | G28: Dave | H28: 2021 | I28: Activo
A29: 25 | B29: CLI-019 | C29: =IF(B29="","",_xlfn.XLOOKUP(B29,CLIENTES!$A$4:$A$53,CLIENTES!$B$4:$B$53,"NO ENCONTRADO")) -> SEBASTIAN CUNHA | D29: CORPORATIVO | E29: =IF(D29="","",_xlfn.XLOOKUP(D29,CLASIFICACIONES!$A$4:$A$10,CLASIFICACIONES!$B$4:$B$10,"")&"-"&TEXT(COUNTIF($D$5:D28,D29)+1,"000")) -> CORP-022 | F29: DAGDA GLOBAL, S.A. | G29: Dave | H29: 2024
A30: 26 | B30: CLI-017 | C30: =IF(B30="","",_xlfn.XLOOKUP(B30,CLIENTES!$A$4:$A$53,CLIENTES!$B$4:$B$53,"NO ENCONTRADO")) -> YOM TOB TOBI TAWACHI | D30: CORPORATIVO | E30: =IF(D30="","",_xlfn.XLOOKUP(D30,CLASIFICACIONES!$A$4:$A$10,CLASIFICACIONES!$B$4:$B$10,"")&"-"&TEXT(COUNTIF($D$5:D29,D30)+1,"000")) -> CORP-023 | F30: ETOMORONI, S.A. | G30: Dave | H30: 2024
A31: 27 | B31: CLI-020 | C31: =IF(B31="","",_xlfn.XLOOKUP(B31,CLIENTES!$A$4:$A$53,CLIENTES!$B$4:$B$53,"NO ENCONTRADO")) -> FRANCO MORALES FLINT | D31: CORPORATIVO | E31: =IF(D31="","",_xlfn.XLOOKUP(D31,CLASIFICACIONES!$A$4:$A$10,CLASIFICACIONES!$B$4:$B$10,"")&"-"&TEXT(COUNTIF($D$5:D30,D31)+1,"000")) -> CORP-024 | F31: INVERSIONES FRAJA, S.A. | G31: Mile | H31: 2025
A32: 28 | B32: CLI-014 | C32: =IF(B32="","",_xlfn.XLOOKUP(B32,CLIENTES!$A$4:$A$53,CLIENTES!$B$4:$B$53,"NO ENCONTRADO")) -> ANGEL RICARDO MARTINEZ BENOIT | D32: CORPORATIVO | E32: =IF(D32="","",_xlfn.XLOOKUP(D32,CLASIFICACIONES!$A$4:$A$10,CLASIFICACIONES!$B$4:$B$10,"")&"-"&TEXT(COUNTIF($D$5:D31,D32)+1,"000")) -> CORP-025 | F32: EASYCOMM, S.A. | G32: Dave | H32: 2025
A33: 29 | B33: CLI-021 | C33: =IF(B33="","",_xlfn.XLOOKUP(B33,CLIENTES!$A$4:$A$53,CLIENTES!$B$4:$B$53,"NO ENCONTRADO")) -> FREDDY ARIAS | D33: CORPORATIVO | E33: =IF(D33="","",_xlfn.XLOOKUP(D33,CLASIFICACIONES!$A$4:$A$10,CLASIFICACIONES!$B$4:$B$10,"")&"-"&TEXT(COUNTIF($D$5:D32,D33)+1,"000")) -> CORP-026 | F33: FUNDACIÓN HERMANOS ARIAS | G33: Dave | H33: 2025
A34: 30 | B34: CLI-021 | C34: =IF(B34="","",_xlfn.XLOOKUP(B34,CLIENTES!$A$4:$A$53,CLIENTES!$B$4:$B$53,"NO ENCONTRADO")) -> FREDDY ARIAS | D34: CORPORATIVO | E34: =IF(D34="","",_xlfn.XLOOKUP(D34,CLASIFICACIONES!$A$4:$A$10,CLASIFICACIONES!$B$4:$B$10,"")&"-"&TEXT(COUNTIF($D$5:D33,D34)+1,"000")) -> CORP-027 | F34: GRUPO HERMANOS ARIAS, S.A. | G34: Dave | H34: 2025
A35: 31 | B35: CLI-006 | C35: =IF(B35="","",_xlfn.XLOOKUP(B35,CLIENTES!$A$4:$A$53,CLIENTES!$B$4:$B$53,"NO ENCONTRADO")) -> JONATHAN ISAAC MIZRACHI MADURO | D35: CORPORATIVO | E35: =IF(D35="","",_xlfn.XLOOKUP(D35,CLASIFICACIONES!$A$4:$A$10,CLASIFICACIONES!$B$4:$B$10,"")&"-"&TEXT(COUNTIF($D$5:D34,D35)+1,"000")) -> CORP-028 | F35: MEI TOWER 9D, S.A. | G35: Mile | H35: 2025
A36: 32 | B36: CLI-006 | C36: =IF(B36="","",_xlfn.XLOOKUP(B36,CLIENTES!$A$4:$A$53,CLIENTES!$B$4:$B$53,"NO ENCONTRADO")) -> JONATHAN ISAAC MIZRACHI MADURO | D36: CORPORATIVO | E36: =IF(D36="","",_xlfn.XLOOKUP(D36,CLASIFICACIONES!$A$4:$A$10,CLASIFICACIONES!$B$4:$B$10,"")&"-"&TEXT(COUNTIF($D$5:D35,D36)+1,"000")) -> CORP-029 | F36: MEI TOWER 10D, S.A. | G36: Mile | H36: 2025
A37: 33 | B37: CLI-006 | C37: =IF(B37="","",_xlfn.XLOOKUP(B37,CLIENTES!$A$4:$A$53,CLIENTES!$B$4:$B$53,"NO ENCONTRADO")) -> JONATHAN ISAAC MIZRACHI MADURO | D37: CORPORATIVO | E37: =IF(D37="","",_xlfn.XLOOKUP(D37,CLASIFICACIONES!$A$4:$A$10,CLASIFICACIONES!$B$4:$B$10,"")&"-"&TEXT(COUNTIF($D$5:D36,D37)+1,"000")) -> CORP-030 | F37: MEI TOWER 12D, S.A. | G37: Mile | H37: 2025
A38: 34 | B38: CLI-006 | C38: =IF(B38="","",_xlfn.XLOOKUP(B38,CLIENTES!$A$4:$A$53,CLIENTES!$B$4:$B$53,"NO ENCONTRADO")) -> JONATHAN ISAAC MIZRACHI MADURO | D38: CORPORATIVO | E38: =IF(D38="","",_xlfn.XLOOKUP(D38,CLASIFICACIONES!$A$4:$A$10,CLASIFICACIONES!$B$4:$B$10,"")&"-"&TEXT(COUNTIF($D$5:D37,D38)+1,"000")) -> CORP-031 | F38: MEI TOWER 1B, S.A. | G38: Mile | H38: 2025
A39: 35 | B39: CLI-006 | C39: =IF(B39="","",_xlfn.XLOOKUP(B39,CLIENTES!$A$4:$A$53,CLIENTES!$B$4:$B$53,"NO ENCONTRADO")) -> JONATHAN ISAAC MIZRACHI MADURO | D39: CORPORATIVO | E39: =IF(D39="","",_xlfn.XLOOKUP(D39,CLASIFICACIONES!$A$4:$A$10,CLASIFICACIONES!$B$4:$B$10,"")&"-"&TEXT(COUNTIF($D$5:D38,D39)+1,"000")) -> CORP-032 | F39: MEI TOWER 1D, S.A. | G39: Mile | H39: 2025
A40: 36 | B40: CLI-006 | C40: =IF(B40="","",_xlfn.XLOOKUP(B40,CLIENTES!$A$4:$A$53,CLIENTES!$B$4:$B$53,"NO ENCONTRADO")) -> JONATHAN ISAAC MIZRACHI MADURO | D40: CORPORATIVO | E40: =IF(D40="","",_xlfn.XLOOKUP(D40,CLASIFICACIONES!$A$4:$A$10,CLASIFICACIONES!$B$4:$B$10,"")&"-"&TEXT(COUNTIF($D$5:D39,D40)+1,"000")) -> CORP-033 | F40: MEI TOWER 2C, S.A. | G40: Mile | H40: 2025
... A48: 44 | B48: CLI-022 | C48: =IF(B48="","",_xlfn.XLOOKUP(B48,CLIENTES!$A$4:$A$53,CLIENTES!$B$4:$B$53,"NO ENCONTRADO")) -> RAYMOND MIZRACHI | D48: CORPORATIVO | E48: =IF(D48="","",_xlfn.XLOOKUP(D48,CLASIFICACIONES!$A$4:$A$10,CLASIFICACIONES!$B$4:$B$10,"")&"-"&TEXT(COUNTIF($D$5:D47,D48)+1,"000")) -> CORP-041 | F48: MEI TOWER 1C, S.A. | G48: Mile | H48: 2025
...

Sheet CLASIFICACIONES
A1: CATÁLOGO DE CLASIFICACIONES — INTEGRA LEGAL
A3: CLASIFICACIÓN | B3: PREFIJO | C3: COLOR ASIGNADO | D3: DESCRIPCIÓN
A4: CORPORATIVO | B4: CORP | D4: Constitución de sociedades, actas, reformas, poderes, cesiones, disoluciones
A5: MIGRACIÓN | B5: MIG | D5: Permisos de trabajo, residencias, visas, trámites migratorios
A6: LABORAL | B6: LAB | D6: Contratos, terminaciones, demandas laborales, reglamentos internos
A7: PENAL | B7: PEN | D7: Denuncias, querellas, defensas penales, procesos penales
A8: CIVIL | B8: CIV | D8: Demandas civiles, procesos de cobro, sucesiones, contratos civiles
A9: ADMINISTRATIVO | B9: ADM | D9: Licencias, permisos, avisos de operación, trámites gubernamentales
A10: REGULATORIO | B10: REG | D10: Cumplimiento regulatorio, reportes AML/GAFI, auditorías, inspecciones
A13: SISTEMA DE NUMERACIÓN: [PREFIJO]-[NNN] → Ejemplo: CORP-001, MIG-002, LAB-003

Sheet CLIENTES
A1: DIRECTORIO DE CLIENTES — INTEGRA LEGAL
A3: N° CLIENTE | B3: NOMBRE / RAZÓN SOCIAL | C3: RUC / CÉDULA | D3: TIPO | E3: CONTACTO PRINCIPAL | F3: TELÉFONO | G3: CORREO | H3: OBSERVACIONES
A4: CLI-001 | B4: JUMBO CAPITAL, S.A. | D4: Corporativo | E4: MARIA GABRIELA LEGENDRE | F4: 6671-3733 | G4: cadasapma@cwpanama.net
A5: CLI-002 | B5: GUILLERMO ROTHPFLUG | C5: E-8-197302 | D5: Corporativo | E5: GUILLERMO ROTHPFLUG | F5: (+55) 11964336047 | G5: guillermo@veriongroup.com | H5: VG LOGISTICS, INC. - VERION PANAMÁ, S.A. - HIDROMEC
A6: CLI-003 | B6: RODRIGO MARROQUIN | D6: Regulatorio | E6: Heriberto Hidalgo | F6: (+51) 986635310 | G6: heriberto.hidalgo@hermani.pe
A7: CLI-004 | B7: ERIC REINALDO BATISTA DOMINGUEZ | C7: 7-705-2229 | D7: Corporativo | E7: Eric Batista | F7: 6800-7929 | G7: ebatista2107@gmail.com | H7: DOWNCOUNTRY BIKE CORP. - GRUPO MELER, S.A. - GLOBAL SPORT LATAM, INC.
A8: CLI-005 | B8: MAIKOL FENG | D8: Corporativo | E8: Maikol Feng | F8: 6906-6647 | H8: INMOBILIARIA FUNG, S.A.
A9: CLI-006 | B9: JONATHAN ISAAC MIZRACHI MADURO | C9: 8-499-309 | E9: Jonathan Mizrachi | F9: 6612-6526 | G9: jmizrachi@procasapanama.com | H9: PPA CONDADO, S.A.
A10: CLI-007 | B10: LORENA LYA BERENGUER RÍOS | C10: 6-708-1415 | D10: Corporativo | E10: LORENA LYA BERENGUER RÍOS | F10: 66541129 | G10: djuridicospanama@gmail.com | H10: FUNDACION NUEVAS CRIATURAS, COMERCIALIZADORA HIZO
A11: CLI-008 | B11: KURT ARTHUR SÁENZ ALBRECHT | D11: Corporativo | E11: JENYRE JIMENEZ | F11: 6648-3707 | G11: jenyrejimenezparra@gmail.com | H11: SAJIMO CORP.
A12: CLI-009 | B12: DIMEDISA, S.A. | D12: Regulatorio | E12: Linda Miranda | G12: regente.calidad@dimedisa.com | H12: Temas Regulatorios
A13: CLI-010 | B13: ANALIDA ARANGO FIDANQUE | D13: Corporativo | E13: Analida Arango | F13: 6676-8402 | G13: analidaarango@gmail.com | H13: Fundacion de interés privado
A14: CLI-011 | B14: LUIS ANTONIO ZELAYA | D14: Corporativo | E14: Luis Antonio Zelaya | F14: 6618-7555 | G14: lzelaya@productividadpersonal.org | H14: Sociedad Anónima
A15: CLI-012 | B15: DANIEL ALVARADO | D15: Corporativo | E15: Daniel Alvarado
A16: CLI-013 | B16: MADELENE MERCADO | D16: Corporativo | E16: Madelene Mercado
A17: CLI-014 | B17: ANGEL RICARDO MARTINEZ BENOIT | C17: 8-776-832 | D17: Corporativo | E17: Angel Ricardo Martinez
A18: CLI-015 | B18: MARLENYS IVETH CHACÓN | C18: 8-966-685 | D18: Corporativo
A19: CLI-016 | B19: YOUSSEF ALI JAAFAR HARB | C19: 8-830-706 | D19: Corporativo
A20: CLI-017 | B20: YOM TOB TOBI TAWACHI | C20: 3-66-1092 | D20: Corporativo
A21: CLI-018 | B21: NAHUEL GALEANO LERNER
A22: CLI-019 | B22: SEBASTIAN CUNHA | C22: AAH646224 | D22: Corporativo | E22: Sebastian Cunha
A23: CLI-020 | B23: FRANCO MORALES FLINT
A24: CLI-021 | B24: FREDDY ARIAS | C24: N-20-2149 | D24: Corporativo | E24: Freddy Arias
A25: CLI-022 | B25: RAYMOND MIZRACHI | C25: 8-730-613
A26: CLI-023 | B26: CARLOS ENRIQUE PULIDO | C26: E-8-154270 | D26: corporativo | E26: CARLOS ENRIQUE PULIDO | F26: 6780-3138 | H26: Corporativo- comercial
A27: CLI-024
A28: CLI-025
A29: CLI-026
A30: CLI-027
A31: CLI-028
A32: CLI-029
A33: CLI-030
A34: CLI-031
A35: CLI-032
A36: CLI-033
A37: CLI-034
A38: CLI-035
... A53: CLI-050
